<?xml version="1.0"?>
<robot name="piatek">

<!-- * * * Link Definitions * * * -->

  <link name="base_link">
    <visual>
      <geometry>
        <box size="0.32 0.26 0.085"/>
      </geometry>
      <material name="blak"/>
    </visual>
  </link>

  <link name="upper_base_link">
    <visual>
      <origin xyz="0 0 0.15" rpy="0 0 0" />
      <geometry>
        <cylinder radius="0.085" length="0.30" />
      </geometry>
      <material name="Cyan1">
        <color rgba="0 0.9 0.9 1.0"/>
      </material>
     </visual>
  </link>

  <link name="camera_link">
    <visual>
      <origin xyz="0 0.1 0.25" rpy="0 0 0" />
      <geometry>
        <box size="0.05 0.05 0.02"/>
      </geometry>
      <material name="blue">
        <color rgba="0 0 .8 1"/>
      </material>
    </visual>
  </link>

  <!-- WHEEL-LINKS -->
  <link name = "right_wheel_link">
    <visual>
      <origin xyz = "0.05 0 0.05" rpy = "0 -1.57 0" />
      <geometry>
        <cylinder length="0.05" radius="0.075"/>
      </geometry>
      <material name = "green">
        <color rgba="0 1 .5 1"/>
      </material>
    </visual>
    <collision>
      <origin xyz = "0.05 0 0.05" rpy = "0 -1.57 0" />
      <geometry>
        <cylinder length="0.05" radius="0.075"/>
      </geometry>
    </collision>
    <inertial>
      <mass value="1"/>
      <inertia ixx="1.0" ixy="0.0" ixz="0.0" iyy="1.0" iyz="0.0" izz="1.0"/>
    </inertial>
  </link>

  <link name = "left_wheel_link">
    <visual>
      <origin xyz = "-0.315 0 0.05" rpy = "0 -1.57 0" />
      <geometry>
        <cylinder length="0.05" radius="0.075"/>
      </geometry>
      <material name = "green">
        <color rgba="0 1 .5 1"/>
      </material>
    </visual>
    <collision>
      <origin xyz = "0.05 0 0.05" rpy = "0 -1.57 0" />
      <geometry>
        <cylinder length="0.05" radius="0.075"/>
      </geometry>
    </collision>
    <inertial>
      <mass value="1"/>
      <inertia ixx="1.0" ixy="0.0" ixz="0.0" iyy="1.0" iyz="0.0" izz="1.0"/>
    </inertial>
  </link>

<!-- * * * Joint Definitions * * * -->
  <joint name="base_to_upper_base_joint" type="fixed">
      <parent link="base_link" />
      <child link="upper_base_link" />
      <origin xyz="0 0 0" rpy="0 0 0" />
  </joint>

  <joint name="upper_base_to_camera_joint" type="revolute">
      <parent link="upper_base_link" />
      <child link="camera_link" />
      <origin xyz="0 0 0" rpy="0 0 0" />
      <axis xyz="0 0 1" />
      <limit lower="-3.1416" upper="3.1416" effort="10" velocity="3" />
  </joint>

  <!-- WHEEL-JOINTS -->
  <joint name="right_wheel_joint" type="continuous">
    <parent link="base_link"/>
    <child link="right_wheel_link"/>
    <origin rpy="0 0 0" xyz="0.133333333333 0 -0.085"/>
    <axis rpy="0 0 0" xyz="1 0 0"/>
  </joint>

  <joint name="left_wheel_joint" type="continuous">
    <parent link="base_link"/>
    <child link="left_wheel_link"/>
    <origin rpy="0 0 0" xyz="0.133333333333 0 -0.085"/>
    <axis rpy="0 0 0" xyz="1 0 0"/>
  </joint>

</robot>
